Traceback (most recent call last):
  File "c:\users\public\programs\anaconda3\lib\site-packages\jupyter_cache\executors\utils.py", line 51, in single_nb_execution
    executenb(
  File "c:\users\public\programs\anaconda3\lib\site-packages\nbclient\client.py", line 1112, in execute
    return NotebookClient(nb=nb, resources=resources, km=km, **kwargs).execute()
  File "c:\users\public\programs\anaconda3\lib\site-packages\nbclient\util.py", line 74, in wrapped
    return just_run(coro(*args, **kwargs))
  File "c:\users\public\programs\anaconda3\lib\site-packages\nbclient\util.py", line 53, in just_run
    return loop.run_until_complete(coro)
  File "c:\users\public\programs\anaconda3\lib\asyncio\base_events.py", line 616, in run_until_complete
    return future.result()
  File "c:\users\public\programs\anaconda3\lib\site-packages\nbclient\client.py", line 553, in async_execute
    await self.async_execute_cell(
  File "c:\users\public\programs\anaconda3\lib\site-packages\nbclient\client.py", line 857, in async_execute_cell
    self._check_raise_for_error(cell, exec_reply)
  File "c:\users\public\programs\anaconda3\lib\site-packages\nbclient\client.py", line 760, in _check_raise_for_error
    raise CellExecutionError.from_cell_and_msg(cell, exec_reply_content)
nbclient.exceptions.CellExecutionError: An error occurred while executing the following cell:
------------------
# NB: we have resampled the data for the autocorreltion analysis

import statsmodels.tsa.stattools as smt
xacf = smt.ccf(df_train.guide_open.squeeze()[0:1900:50], df_train.head_net.squeeze()[0:1900:50],  adjusted=False)
acf1 = smt.ccf(df_train.guide_open.squeeze()[0:1900:50], df_train.guide_open.squeeze()[0:1900:50],  adjusted=False)
acf2 = smt.ccf(df_train.head_net.squeeze()[0:1900:50], df_train.head_net.squeeze()[0:1900:50],  adjusted=False)


fig, [ax1, ax2, ax3] = plt.subplots(1, 3, sharex=True, figsize=(30,12))
i = 1
for p in xacf:
    x = [i, i]
    ax1.plot([i, i], [0, p],  'b', linewidth=3)
    i= i + 1
ax1.grid(True)
ax1.set_title("Cross ACF between guide-open and Head_net", fontsize=20, color='blue')
ax1.set_xlabel(r'Time Lag: sample frequency $\times$ 5000', fontsize=20, color='blue')


i = 1
for p in acf1:
    x = [i, i]
    ax2.plot([i, i], [0, p],  'b', linewidth=3)
    i= i + 1
ax2.grid(True)
ax2.set_title("ACF of guide-open signal", fontsize=20, color='blue')
ax2.set_xlabel(r'Time Lag: sample frequency $\times$ 5000', fontsize=20, color='blue')

i = 1
for p in acf2:
    x = [i, i]
    ax3.plot([i, i], [0, p],  'b', linewidth=3)
    i= i + 1
ax3.grid(True)
ax3.set_title("ACF ofHead_net", fontsize=20, color='blue')
ax4.set_xlabel(r'Time Lag: sample frequency $\times$ 5000', fontsize=20, color='blue')

plt.show()
------------------

[1;31m---------------------------------------------------------------------------[0m
[1;31mNameError[0m                                 Traceback (most recent call last)
[1;32m~\AppData\Local\Temp/ipykernel_1688/3112472716.py[0m in [0;36m<module>[1;34m[0m
[0;32m     34[0m [0max3[0m[1;33m.[0m[0mgrid[0m[1;33m([0m[1;32mTrue[0m[1;33m)[0m[1;33m[0m[1;33m[0m[0m
[0;32m     35[0m [0max3[0m[1;33m.[0m[0mset_title[0m[1;33m([0m[1;34m"ACF ofHead_net"[0m[1;33m,[0m [0mfontsize[0m[1;33m=[0m[1;36m20[0m[1;33m,[0m [0mcolor[0m[1;33m=[0m[1;34m'blue'[0m[1;33m)[0m[1;33m[0m[1;33m[0m[0m
[1;32m---> 36[1;33m [0max4[0m[1;33m.[0m[0mset_xlabel[0m[1;33m([0m[1;34mr'Time Lag: sample frequency $\times$ 5000'[0m[1;33m,[0m [0mfontsize[0m[1;33m=[0m[1;36m20[0m[1;33m,[0m [0mcolor[0m[1;33m=[0m[1;34m'blue'[0m[1;33m)[0m[1;33m[0m[1;33m[0m[0m
[0m[0;32m     37[0m [1;33m[0m[0m
[0;32m     38[0m [0mplt[0m[1;33m.[0m[0mshow[0m[1;33m([0m[1;33m)[0m[1;33m[0m[1;33m[0m[0m

[1;31mNameError[0m: name 'ax4' is not defined
NameError: name 'ax4' is not defined

